File: Purity/www/example_Benz.acid_20bar.txt
##Temp./°C;Time/min;Pressure/Bar;DSC/(mW/mg);Sensit./(uV/mW)
114.19100;59.42000;19.98453;-6.759130e-002;3.14215
114.20400;59.44667;19.98392;-6.797866e-002;3.14216
114.21900;59.47333;19.98407;-6.758967e-002;3.14217
114.23200;59.50000;19.98377;-6.797703e-002;3.14218
114.24500;59.52667;19.98331;-6.810564e-002;3.14219
114.25900;59.55333;19.98589;-6.849293e-002;3.14220
114.27300;59.58000;19.98544;-6.784528e-002;3.14221
114.28700;59.60667;19.98665;-6.823258e-002;3.14222
114.30000;59.63333;19.98483;-6.836118e-002;3.14223
114.31300;59.66000;19.98725;-6.810169e-002;3.14224
114.32600;59.68667;19.98559;-6.835967e-002;3.14225
114.33900;59.71333;19.98619;-6.861765e-002;3.14226
114.35400;59.74000;19.98589;-6.809932e-002;3.14227
114.36600;59.76667;19.98513;-6.835735e-002;3.14228
114.38000;59.79333;19.98756;-6.822717e-002;3.14229
114.39300;59.82000;19.98635;-6.822641e-002;3.14230
114.40900;59.84667;19.98650;-6.874295e-002;3.14231
114.42000;59.87333;19.98574;-6.887167e-002;3.14232
114.43500;59.90000;19.98347;-6.848270e-002;3.14233
114.44800;59.92667;19.98438;-6.887004e-002;3.14234
114.46300;59.95333;19.98422;-6.886917e-002;3.14236
114.47500;59.98000;19.98271;-6.848038e-002;3.14237
114.48900;60.00667;19.98225;-6.886766e-002;3.14238
114.50100;60.03333;19.98407;-6.912568e-002;3.14239
114.51300;60.06000;19.98271;-6.821946e-002;3.14239
114.52700;60.08667;19.98347;-6.873609e-002;3.14240
114.54100;60.11333;19.98240;-6.873528e-002;3.14242
114.55400;60.14000;19.98316;-6.834644e-002;3.14243
114.56600;60.16667;19.98468;-6.873382e-002;3.14243
114.57800;60.19333;19.98377;-6.756889e-002;3.14244
114.59300;60.22000;19.98377;-6.834417e-002;3.14246
114.60700;60.24667;19.98225;-6.860207e-002;3.14247
114.62000;60.27333;19.98377;-6.860133e-002;3.14248
114.63400;60.30000;19.98271;-6.795372e-002;3.14249
114.64800;60.32667;19.98195;-6.898777e-002;3.14250
114.66200;60.35333;19.98180;-6.924566e-002;3.14251
114.67500;60.38000;19.98316;-6.898620e-002;3.14252
114.68900;60.40667;19.98134;-6.885603e-002;3.14253
114.70100;60.43333;19.98301;-6.885534e-002;3.14254
114.71600;60.46000;19.98362;-6.911317e-002;3.14255
114.72800;60.48667;19.98559;-6.885376e-002;3.14256
114.74200;60.51333;19.98301;-6.872360e-002;3.14257
114.75500;60.54000;19.98544;-6.898155e-002;3.14258
114.76800;60.56667;19.98286;-6.975692e-002;3.14259
114.78100;60.59333;19.98195;-6.898003e-002;3.14260
114.79400;60.62000;19.98210;-6.923799e-002;3.14261
114.80800;60.64667;19.98256;-6.923718e-002;3.14262
114.82100;60.67333;19.98316;-6.871902e-002;3.14263
114.83400;60.70000;19.97953;-6.845956e-002;3.14264
114.84900;60.72667;19.97938;-6.807063e-002;3.14265
114.86100;60.75333;19.98044;-6.858734e-002;3.14266
114.87500;60.78000;19.98074;-6.819848e-002;3.14267
114.88700;60.80667;19.98104;-6.845649e-002;3.14268
114.89900;60.83333;19.98119;-6.884384e-002;3.14269
114.91300;60.86000;19.98150;-6.884303e-002;3.14270
114.92700;60.88667;19.98271;-6.832482e-002;3.14271
114.94000;60.91333;19.98286;-6.819472e-002;3.14272
114.95500;60.94000;19.98498;-6.909929e-002;3.14273
114.96700;60.96667;19.98619;-6.883989e-002;3.14274
114.98100;60.99333;19.98619;-6.909778e-002;3.14275
114.99300;61.02000;19.98604;-6.845035e-002;3.14276
115.00600;61.04667;19.98650;-6.883764e-002;3.14277
115.01900;61.07333;19.98468;-6.909557e-002;3.14278
115.03100;61.10000;19.98422;-6.831880e-002;3.14279
115.04500;61.12667;19.98528;-6.883538e-002;3.14280
115.05700;61.15333;19.98347;-6.909337e-002;3.14281
115.07200;61.18000;19.98286;-6.844578e-002;3.14282
115.08500;61.20667;19.98407;-6.922109e-002;3.14283
115.09900;61.23333;19.98392;-6.883225e-002;3.14284
115.11200;61.26000;19.98407;-6.960755e-002;3.14285
115.12600;61.28667;19.98468;-6.960675e-002;3.14286
115.14000;61.31333;19.98513;-7.012329e-002;3.14287
115.15400;61.34000;19.98544;-6.999313e-002;3.14288
115.16600;61.36667;19.98438;-6.921640e-002;3.14289
115.18000;61.39333;19.98468;-6.973294e-002;3.14290
115.19300;61.42000;19.98362;-6.934417e-002;3.14291
115.20700;61.44667;19.98362;-6.921401e-002;3.14292
115.22000;61.47333;19.98240;-6.843723e-002;3.14293
115.23400;61.50000;19.98544;-6.972980e-002;3.14294
115.24800;61.52667;19.98589;-6.947031e-002;3.14295
115.26200;61.55333;19.98347;-6.895215e-002;3.14296
115.27500;61.58000;19.98377;-6.856338e-002;3.14297
115.28900;61.60667;19.98240;-6.959727e-002;3.14298
115.30300;61.63333;19.98165;-6.946713e-002;3.14299
115.31600;61.66000;19.98225;-6.946637e-002;3.14300
115.32800;61.68667;19.98286;-7.011235e-002;3.14301
115.34200;61.71333;19.98286;-6.959420e-002;3.14302
115.35600;61.74000;19.98240;-6.998140e-002;3.14303
115.36800;61.76667;19.98165;-6.972203e-002;3.14304
115.38300;61.79333;19.98347;-6.972115e-002;3.14305
115.39500;61.82000;19.98407;-6.933246e-002;3.14306
115.40700;61.84667;19.98316;-6.894376e-002;3.14307
115.42100;61.87333;19.98331;-6.855496e-002;3.14308
115.43400;61.90000;19.98422;-6.945953e-002;3.14309
115.45000;61.92667;19.98422;-7.010527e-002;3.14310
115.46300;61.95333;19.98362;-6.894052e-002;3.14311
115.47600;61.98000;19.98316;-6.868111e-002;3.14312
115.48900;62.00667;19.98347;-6.906836e-002;3.14313
115.50300;62.03333;19.98301;-6.919688e-002;3.14314
115.51700;62.06000;19.98468;-6.945473e-002;3.14315
115.52900;62.08667;19.98468;-6.893671e-002;3.14316
115.54300;62.11333;19.98498;-6.971188e-002;3.14317
115.55800;62.14000;19.98513;-6.971101e-002;3.14318
115.57100;62.16667;19.98438;-6.971026e-002;3.14319
115.58300;62.19333;19.98483;-6.970956e-002;3.14320
115.59600;62.22000;19.98377;-6.970882e-002;3.14321
115.60800;62.24667;19.98286;-6.944946e-002;3.14322
115.62100;62.27333;19.98195;-6.931938e-002;3.14323
115.63400;62.30000;19.98316;-6.957728e-002;3.14324
115.64800;62.32667;19.98453;-6.905917e-002;3.14325
115.66100;62.35333;19.98392;-6.931707e-002;3.14326
115.67300;62.38000;19.98544;-6.854042e-002;3.14327
115.68600;62.40667;19.98513;-6.841035e-002;3.14328
115.70000;62.43333;19.98468;-6.866819e-002;3.14329
115.71400;62.46000;19.98710;-6.905536e-002;3.14330
115.72700;62.48667;19.98422;-6.905461e-002;3.14331
115.74000;62.51333;19.98468;-6.866588e-002;3.14332
115.75400;62.54000;19.98604;-6.931170e-002;3.14333
115.76800;62.56667;19.98635;-6.969886e-002;3.14334
115.78200;62.59333;19.98498;-6.943940e-002;3.14335
115.79500;62.62000;19.98453;-6.930933e-002;3.14336
115.80900;62.64667;19.98407;-6.956716e-002;3.14337
115.82200;62.67333;19.98453;-7.047166e-002;3.14338
115.83600;62.70000;19.98498;-6.982424e-002;3.14339
115.84800;62.72667;19.98635;-6.982354e-002;3.14340
115.86200;62.75333;19.98422;-7.008138e-002;3.14341
115.87400;62.78000;19.98513;-7.033932e-002;3.14342
115.88700;62.80667;19.98362;-6.917470e-002;3.14343
115.90000;62.83333;19.98347;-6.969123e-002;3.14344
115.91500;62.86000;19.98468;-7.020763e-002;3.14345
115.92800;62.88667;19.98528;-7.007756e-002;3.14346
115.94200;62.91333;19.98574;-6.917153e-002;3.14347
115.95500;62.94000;19.98286;-6.942941e-002;3.14348
115.96800;62.96667;19.98422;-7.059251e-002;3.14349
115.98400;62.99333;19.98650;-7.020363e-002;3.14350
115.99700;63.02000;19.98574;-7.020288e-002;3.14351
116.01000;63.04667;19.98453;-7.046076e-002;3.14352
116.02200;63.07333;19.98483;-7.110664e-002;3.14353
116.03600;63.10000;19.98180;-7.007131e-002;3.14354
116.05100;63.12667;19.98240;-7.058770e-002;3.14355
116.06400;63.15333;19.98438;-7.032832e-002;3.14356
116.07800;63.18000;19.98589;-7.058613e-002;3.14357
116.09200;63.20667;19.98650;-7.071464e-002;3.14358
116.10400;63.23333;19.98695;-6.955013e-002;3.14359
116.11600;63.26000;19.98468;-6.980806e-002;3.14360
116.13000;63.28667;19.98483;-6.967794e-002;3.14361
116.14300;63.31333;19.98438;-7.019444e-002;3.14362
116.15700;63.34000;19.98483;-7.019363e-002;3.14363
116.17000;63.36667;19.98483;-7.045149e-002;3.14364
116.18500;63.39333;19.98438;-7.006270e-002;3.14365
116.19800;63.42000;19.98422;-7.032057e-002;3.14366
116.21000;63.44667;19.98422;-7.019056e-002;3.14367
116.22400;63.47333;19.98362;-7.018976e-002;3.14368
116.23700;63.50000;19.98256;-7.044762e-002;3.14369
116.25000;63.52667;19.98119;-7.018825e-002;3.14370
116.26500;63.55333;19.98559;-7.083393e-002;3.14371
116.27600;63.58000;19.98498;-7.057467e-002;3.14371
116.28900;63.60667;19.98422;-6.992739e-002;3.14372
116.30200;63.63333;19.98498;-6.966802e-002;3.14373
116.31600;63.66000;19.98377;-7.057236e-002;3.14374
116.32800;63.68667;19.98468;-7.005445e-002;3.14375
116.34200;63.71333;19.98422;-6.992434e-002;3.14376
116.35500;63.74000;19.98377;-6.940636e-002;3.14377
116.37100;63.76667;19.98316;-6.953475e-002;3.14378
116.38300;63.79333;19.98316;-6.940476e-002;3.14379
116.39600;63.82000;19.98377;-7.005053e-002;3.14380
116.40900;63.84667;19.98165;-6.979117e-002;3.14381
116.42100;63.87333;19.98210;-6.991978e-002;3.14382
116.43600;63.90000;19.98331;-7.108264e-002;3.14383
116.45000;63.92667;19.98316;-7.056462e-002;3.14384
116.46300;63.95333;19.98468;-7.082247e-002;3.14385
116.47700;63.98000;19.98498;-7.069237e-002;3.14386
116.49000;64.00667;19.98453;-7.043301e-002;3.14387
116.50400;64.03333;19.98225;-6.978570e-002;3.14388
116.51700;64.06000;19.98377;-7.030215e-002;3.14389
116.53200;64.08667;19.98392;-7.030128e-002;3.14390
116.54400;64.11333;19.98331;-7.042989e-002;3.14391
116.55900;64.14000;19.98347;-7.081692e-002;3.14392
116.57300;64.16667;19.98544;-7.068682e-002;3.14393
116.58400;64.19333;19.98392;-7.094478e-002;3.14394
116.59700;64.22000;19.98438;-7.081472e-002;3.14395
116.61100;64.24667;19.98271;-7.029673e-002;3.14396
116.62400;64.27333;19.98438;-7.081317e-002;3.14397
116.63700;64.30000;19.98650;-7.107101e-002;3.14398
116.64900;64.32667;19.98574;-7.068244e-002;3.14399
116.66300;64.35333;19.98498;-7.029374e-002;3.14400
116.67500;64.38000;19.98665;-7.003446e-002;3.14401
116.68800;64.40667;19.98619;-6.964582e-002;3.14402
116.70100;64.43333;19.98559;-7.042084e-002;3.14402
116.71500;64.46000;19.98604;-7.003215e-002;3.14403
116.72800;64.48667;19.98362;-7.003141e-002;3.14404
116.74000;64.51333;19.98240;-7.016001e-002;3.14405
116.75500;64.54000;19.98301;-7.028844e-002;3.14406
116.76800;64.56667;19.98513;-7.067557e-002;3.14407
116.78100;64.59333;19.98331;-7.015765e-002;3.14408
116.79500;64.62000;19.98483;-7.080330e-002;3.14409
116.80800;64.64667;19.98544;-7.157829e-002;3.14410
116.82200;64.67333;19.98498;-7.093104e-002;3.14411
116.83400;64.70000;19.98680;-7.144750e-002;3.14412
116.84700;64.72667;19.98589;-7.092959e-002;3.14413
116.86200;64.75333;19.98695;-7.079944e-002;3.14414
116.87400;64.78000;19.98589;-7.079874e-002;3.14415
116.88700;64.80667;19.98589;-7.015155e-002;3.14416
116.90100;64.83333;19.98422;-6.989217e-002;3.14417
116.91600;64.86000;19.98635;-7.079632e-002;3.14418
116.93000;64.88667;19.98816;-7.144196e-002;3.14419
116.94300;64.91333;19.98801;-7.079477e-002;3.14420
116.95600;64.94000;19.98877;-7.182831e-002;3.14421
116.96800;64.96667;19.98574;-7.105191e-002;3.14422
116.98100;64.99333;19.98665;-7.156829e-002;3.14423
116.99300;65.02000;19.98665;-7.117975e-002;3.14424
117.00700;65.04667;19.98650;-7.053252e-002;3.14425
117.02100;65.07333;19.98725;-7.143670e-002;3.14426
117.03500;65.10000;19.98589;-7.053090e-002;3.14427
117.04700;65.12667;19.98635;-7.117663e-002;3.14427
117.06200;65.15333;19.98559;-7.104648e-002;3.14429
117.07500;65.18000;19.98574;-7.143359e-002;3.14429
117.08800;65.20667;19.98498;-7.169140e-002;3.14430
117.10100;65.23333;19.98468;-7.169065e-002;3.14431
117.11400;65.26000;19.98559;-7.181918e-002;3.14432
117.12900;65.28667;19.98407;-7.117191e-002;3.14433
117.14100;65.31333;19.98301;-7.168834e-002;3.14434
117.15400;65.34000;19.98392;-7.104118e-002;3.14435
117.16600;65.36667;19.98316;-7.116977e-002;3.14436
117.17900;65.39333;19.98544;-7.142759e-002;3.14437
117.19400;65.42000;19.98468;-7.078033e-002;3.14438
117.20700;65.44667;19.98483;-7.142598e-002;3.14439
117.22000;65.47333;19.98559;-7.142523e-002;3.14440
117.23300;65.50000;19.98619;-7.168303e-002;3.14441
117.24700;65.52667;19.98680;-7.258718e-002;3.14442
117.26200;65.55333;19.98559;-7.116425e-002;3.14443
117.27400;65.58000;19.98665;-7.180995e-002;3.14444
117.28900;65.60667;19.98756;-7.180909e-002;3.14445
117.30200;65.63333;19.98831;-7.193761e-002;3.14446
117.31400;65.66000;19.98786;-7.219547e-002;3.14447
117.32900;65.68667;19.98922;-7.219460e-002;3.14448
117.34200;65.71333;19.98756;-7.154748e-002;3.14449
117.35500;65.74000;19.98635;-7.154672e-002;3.14450
117.36900;65.76667;19.98695;-7.154592e-002;3.14451
117.38200;65.79333;19.98604;-7.219154e-002;3.14451
117.39600;65.82000;19.98847;-7.257855e-002;3.14452
117.40900;65.84667;19.98710;-7.180215e-002;3.14453
117.42200;65.87333;19.98695;-7.167214e-002;3.14454
117.43600;65.90000;19.98710;-7.154206e-002;3.14455
117.44800;65.92667;19.98710;-7.167064e-002;3.14456
117.46400;65.95333;19.98862;-7.166972e-002;3.14457
117.47700;65.98000;19.98710;-7.205678e-002;3.14458
117.49000;66.00667;19.98559;-7.153895e-002;3.14459
117.50400;66.03333;19.98574;-7.231377e-002;3.14460
117.51800;66.06000;19.98407;-7.192515e-002;3.14461
117.53000;66.08667;19.98392;-7.231226e-002;3.14462
117.54500;66.11333;19.98635;-7.282849e-002;3.14463
117.55800;66.14000;19.98589;-7.295700e-002;3.14464
117.57100;66.16667;19.98498;-7.256844e-002;3.14465
117.58400;66.19333;19.98528;-7.217989e-002;3.14466
117.59700;66.22000;19.98589;-7.230840e-002;3.14467
117.61000;66.24667;19.98544;-7.204912e-002;3.14468
117.62400;66.27333;19.98453;-7.191905e-002;3.14469
117.63700;66.30000;19.98498;-7.191830e-002;3.14470
117.64900;66.32667;19.98468;-7.269320e-002;3.14470
117.66400;66.35333;19.98544;-7.269234e-002;3.14471
117.67800;66.38000;19.98725;-7.269153e-002;3.14472
117.69100;66.40667;19.98619;-7.243225e-002;3.14473
117.70500;66.43333;19.98544;-7.191438e-002;3.14474
117.71800;66.46000;19.98710;-7.243069e-002;3.14475
117.73200;66.48667;19.98498;-7.191283e-002;3.14476
117.74500;66.51333;19.98392;-7.229987e-002;3.14477
117.75900;66.54000;19.98589;-7.255759e-002;3.14478
117.77300;66.56667;19.98665;-7.281531e-002;3.14479
117.78600;66.59333;19.98665;-7.255603e-002;3.14480
117.80000;66.62000;19.98816;-7.294301e-002;3.14481
117.81200;66.64667;19.98695;-7.371789e-002;3.14482
117.82600;66.67333;19.98604;-7.371708e-002;3.14483
117.84000;66.70000;19.98589;-7.410406e-002;3.14484
117.85500;66.72667;19.98544;-7.345688e-002;3.14485
117.86800;66.75333;19.98589;-7.384391e-002;3.14486
117.88000;66.78000;19.98604;-7.384322e-002;3.14487
117.89300;66.80667;19.98665;-7.384247e-002;3.14488
117.90600;66.83333;19.98635;-7.397097e-002;3.14489
117.91800;66.86000;19.98544;-7.306547e-002;3.14489
117.93100;66.88667;19.98619;-7.345249e-002;3.14490
117.94300;66.91333;19.98528;-7.319328e-002;3.14491
117.95600;66.94000;19.98574;-7.345104e-002;3.14492
117.96900;66.96667;19.98589;-7.396732e-002;3.14493
117.98200;66.99333;19.98513;-7.370806e-002;3.14494
117.99600;67.02000;19.98741;-7.448279e-002;3.14495
118.00900;67.04667;19.98453;-7.370650e-002;3.14496
118.02100;67.07333;19.98331;-7.331804e-002;3.14497
118.03400;67.10000;19.98650;-7.383430e-002;3.14498
118.04800;67.12667;19.98619;-7.447977e-002;3.14499
118.06300;67.15333;19.98513;-7.473741e-002;3.14500
118.07600;67.18000;19.98286;-7.447815e-002;3.14500
118.09000;67.20667;19.98468;-7.551136e-002;3.14501
118.10400;67.23333;19.98559;-7.589831e-002;3.14502
118.11800;67.26000;19.98604;-7.615600e-002;3.14503
118.13000;67.28667;19.98680;-7.654306e-002;3.14504
118.14400;67.31333;19.98483;-7.667150e-002;3.14505
118.15700;67.34000;19.98468;-7.667074e-002;3.14506
118.17100;67.36667;19.98528;-7.809168e-002;3.14507
118.18400;67.39333;19.98544;-7.757391e-002;3.14508
118.19700;67.42000;19.98377;-7.744391e-002;3.14509
118.21100;67.44667;19.98786;-7.860633e-002;3.14510
118.22500;67.47333;19.98953;-7.834701e-002;3.14511
118.23900;67.50000;19.98710;-7.847544e-002;3.14512
118.25200;67.52667;19.98801;-7.808693e-002;3.14513
118.26500;67.55333;19.98725;-7.924940e-002;3.14514
118.27700;67.58000;19.98831;-7.924869e-002;3.14515
118.29000;67.60667;19.98695;-7.976493e-002;3.14515
118.30300;67.63333;19.98725;-7.963491e-002;3.14516
118.31700;67.66000;19.98831;-7.963408e-002;3.14517
118.32900;67.68667;19.98771;-7.937487e-002;3.14518
118.34200;67.71333;19.98877;-7.950336e-002;3.14519
118.35600;67.74000;19.98953;-8.001951e-002;3.14520
118.37000;67.76667;19.98831;-8.105265e-002;3.14521
118.38400;67.79333;19.98756;-8.131031e-002;3.14522
118.39800;67.82000;19.98953;-8.260194e-002;3.14523
118.41100;67.84667;19.98725;-8.350587e-002;3.14524
118.42400;67.87333;19.98983;-8.376358e-002;3.14525
118.43800;67.90000;19.99028;-8.376274e-002;3.14526
118.45000;67.92667;19.99059;-8.389126e-002;3.14527
118.46300;67.95333;19.99195;-8.389048e-002;3.14527
118.47700;67.98000;19.99059;-8.350192e-002;3.14528
118.49000;68.00667;19.99165;-8.363039e-002;3.14529
118.50300;68.03333;19.99059;-8.350037e-002;3.14530
118.51700;68.06000;19.99286;-8.324105e-002;3.14531
118.52900;68.08667;19.99240;-8.324034e-002;3.14532
118.54200;68.11333;19.99043;-8.298108e-002;3.14533
118.55600;68.14000;19.99119;-8.259252e-002;3.14534
118.56800;68.16667;19.99028;-8.233333e-002;3.14535
118.58200;68.19333;19.99059;-8.310793e-002;3.14536
118.59700;68.22000;19.99240;-8.349476e-002;3.14537
118.60900;68.24667;19.99059;-8.336480e-002;3.14538
118.62200;68.27333;19.99119;-8.465640e-002;3.14538
118.63700;68.30000;19.99195;-8.465551e-002;3.14539
118.64900;68.32667;19.99210;-8.478402e-002;3.14540
118.66300;68.35333;19.98998;-8.530013e-002;3.14541
118.67800;68.38000;19.99013;-8.555771e-002;3.14542
118.69000;68.40667;19.99028;-8.529851e-002;3.14543
118.70400;68.43333;19.98831;-8.503920e-002;3.14544
118.71700;68.46000;19.98922;-8.542613e-002;3.14545
118.73000;68.48667;19.98862;-8.516688e-002;3.14546
118.74500;68.51333;19.98665;-8.581215e-002;3.14547
118.75700;68.54000;19.98892;-8.542373e-002;3.14548
118.77000;68.56667;19.98937;-8.490601e-002;3.14549
118.78300;68.59333;19.98756;-8.542217e-002;3.14550
118.79600;68.62000;19.98831;-8.516292e-002;3.14550
118.80800;68.64667;19.98862;-8.606683e-002;3.14551
118.82100;68.67333;19.98907;-8.451525e-002;3.14552
118.83400;68.70000;19.98922;-8.490218e-002;3.14553
118.84700;68.72667;19.98892;-8.490140e-002;3.14554
118.86300;68.75333;19.98771;-8.412505e-002;3.14555
118.87400;68.78000;19.98589;-8.296132e-002;3.14556
118.89000;68.80667;19.98635;-8.192651e-002;3.14557
118.90400;68.83333;19.98771;-8.115031e-002;3.14558
118.91800;68.86000;19.98786;-8.192486e-002;3.14559
118.93100;68.88667;19.98756;-8.127794e-002;3.14560
118.94400;68.91333;19.98741;-8.114795e-002;3.14561
118.95700;68.94000;19.98392;-8.050103e-002;3.14561
118.97000;68.96667;19.98498;-7.998335e-002;3.14562
118.98400;68.99333;19.98544;-8.037022e-002;3.14563
118.99700;69.02000;19.98468;-7.998177e-002;3.14564
119.01000;69.04667;19.98453;-7.933486e-002;3.14565
119.02400;69.07333;19.98695;-7.972173e-002;3.14566
119.03800;69.10000;19.98544;-7.907477e-002;3.14567
119.05100;69.12667;19.98544;-7.868634e-002;3.14568
119.06300;69.15333;19.98635;-7.855641e-002;3.14569
119.07700;69.18000;19.98665;-7.752179e-002;3.14570
119.09000;69.20667;19.98604;-7.752103e-002;3.14571
119.10300;69.23333;19.98574;-7.790794e-002;3.14571
119.11600;69.26000;19.98847;-7.764874e-002;3.14572
119.12900;69.28667;19.98741;-7.738954e-002;3.14573
119.14300;69.31333;19.98710;-7.738873e-002;3.14574
119.15400;69.34000;19.98695;-7.725887e-002;3.14575
119.16800;69.36667;19.98756;-7.738728e-002;3.14576
119.18100;69.39333;19.98877;-7.751574e-002;3.14577
119.19400;69.42000;19.98756;-7.738576e-002;3.14578
119.20700;69.44667;19.98665;-7.777267e-002;3.14579
119.22300;69.47333;19.98998;-7.790097e-002;3.14580
119.23600;69.50000;19.98907;-7.777099e-002;3.14580
119.24900;69.52667;19.98968;-7.764102e-002;3.14581
119.26200;69.55333;19.98862;-7.764025e-002;3.14582
119.27600;69.58000;19.98922;-7.751023e-002;3.14583
119.28900;69.60667;19.98922;-7.802635e-002;3.14584
119.30200;69.63333;19.98907;-7.776715e-002;3.14585
119.31400;69.66000;19.98862;-7.699115e-002;3.14586
119.32700;69.68667;19.98635;-7.724883e-002;3.14587
119.34200;69.71333;19.98710;-7.763561e-002;3.14588
119.35300;69.74000;19.98756;-7.724732e-002;3.14588
119.36700;69.76667;19.99074;-7.789259e-002;3.14589
119.38200;69.79333;19.99013;-7.815016e-002;3.14590
119.39400;69.82000;19.98953;-7.866633e-002;3.14591
119.40700;69.84667;19.98816;-7.879478e-002;3.14592
119.42000;69.87333;19.98892;-7.853559e-002;3.14593
119.43400;69.90000;19.98756;-7.814713e-002;3.14594
119.44800;69.92667;19.98801;-7.840475e-002;3.14595
119.46300;69.95333;19.98862;-7.853309e-002;3.14596
119.47700;69.98000;19.98907;-7.879070e-002;3.14597
119.49000;70.00667;19.99043;-7.930680e-002;3.14598
119.50400;70.03333;19.99043;-7.943520e-002;3.14599
119.51600;70.06000;19.98801;-7.930529e-002;3.14599
119.53000;70.08667;19.98922;-7.917526e-002;3.14600
119.54400;70.11333;19.98937;-7.994971e-002;3.14601
119.55600;70.14000;19.98907;-7.956138e-002;3.14602
119.56900;70.16667;19.98892;-7.981904e-002;3.14603
119.58400;70.19333;19.98922;-8.020580e-002;3.14604
119.59400;70.22000;19.98892;-7.917153e-002;3.14605
119.60800;70.24667;19.98635;-7.955834e-002;3.14606
119.62100;70.27333;19.98619;-7.852390e-002;3.14607
119.63400;70.30000;19.98559;-7.839393e-002;3.14607
119.64700;70.32667;19.98559;-7.852238e-002;3.14608
119.66300;70.35333;19.98680;-7.903830e-002;3.14609
119.67700;70.38000;19.98831;-7.981273e-002;3.14610
119.69000;70.40667;19.98619;-7.994118e-002;3.14611
119.70400;70.43333;19.98680;-8.019879e-002;3.14612
119.71700;70.46000;19.98422;-8.019802e-002;3.14613
119.73100;70.48667;19.98392;-8.058483e-002;3.14614
119.74400;70.51333;19.98544;-8.071327e-002;3.14615
119.75800;70.54000;19.98741;-8.135849e-002;3.14616
119.77100;70.56667;19.98725;-8.161614e-002;3.14617
119.78500;70.59333;19.98710;-8.174453e-002;3.14618
119.79700;70.62000;19.98619;-8.148541e-002;3.14618
119.81000;70.64667;19.98650;-8.148464e-002;3.14619
119.82400;70.67333;19.98801;-8.174224e-002;3.14620
119.83800;70.70000;19.98619;-8.057857e-002;3.14621
119.85200;70.72667;19.98801;-8.174060e-002;3.14622
119.86700;70.75333;19.98741;-8.173971e-002;3.14623
119.88000;70.78000;19.98665;-8.199735e-002;3.14624
119.89300;70.80667;19.98513;-8.135058e-002;3.14625
119.90700;70.83333;19.98544;-8.264178e-002;3.14626
119.92200;70.86000;19.98725;-8.289930e-002;3.14627
119.93400;70.88667;19.98650;-8.251099e-002;3.14627
119.94800;70.91333;19.98604;-8.289777e-002;3.14628
119.96100;70.94000;19.98544;-8.315541e-002;3.14629
119.97200;70.96667;19.98513;-8.263795e-002;3.14630
119.98600;70.99333;19.98438;-8.315393e-002;3.14631
120.00000;71.02000;19.98468;-8.289471e-002;3.14632
120.01300;71.04667;19.98483;-8.263555e-002;3.14633
120.02500;71.07333;19.98498;-8.237644e-002;3.14634
120.03800;71.10000;19.98544;-8.289247e-002;3.14634
120.05100;71.12667;19.98650;-8.366690e-002;3.14635
120.06600;71.15333;19.98801;-8.302002e-002;3.14636
120.07800;71.18000;19.98680;-8.327771e-002;3.14637
120.09200;71.20667;19.98695;-8.379367e-002;3.14638
120.10600;71.23333;19.98816;-8.405125e-002;3.14639
120.11900;71.26000;19.98771;-8.366289e-002;3.14640
120.13100;71.28667;19.98725;-8.327459e-002;3.14641
120.14400;71.31333;19.98619;-8.327383e-002;3.14641
120.15800;71.34000;19.98468;-8.288541e-002;3.14642
120.17300;71.36667;19.98574;-8.443487e-002;3.14643
120.18500;71.39333;19.98635;-8.469255e-002;3.14644
120.20000;71.42000;19.98635;-8.469167e-002;3.14645
120.21200;71.44667;19.98544;-8.520773e-002;3.14646
120.22500;71.47333;19.98544;-8.507777e-002;3.14647
120.23800;71.50000;19.98650;-8.559377e-002;3.14648
120.25200;71.52667;19.98816;-8.546375e-002;3.14649
120.26500;71.55333;19.98680;-8.559217e-002;3.14649
120.27700;71.58000;19.98741;-8.546227e-002;3.14650
120.29000;71.60667;19.98847;-8.546150e-002;3.14651
120.30500;71.63333;19.98650;-8.507304e-002;3.14652
120.31800;71.66000;19.98847;-8.494307e-002;3.14653
120.33100;71.68667;19.98953;-8.571745e-002;3.14654
120.34400;71.71333;19.98816;-8.649183e-002;3.14655
120.36000;71.74000;19.98831;-8.662006e-002;3.14656
120.37100;71.76667;19.98786;-8.700698e-002;3.14656
120.38500;71.79333;19.98771;-8.739371e-002;3.14657
120.39900;71.82000;19.98831;-8.752207e-002;3.14658
120.41200;71.84667;19.98862;-8.726291e-002;3.14659
120.42500;71.87333;19.98862;-8.700376e-002;3.14660
120.43700;71.90000;19.98665;-8.739061e-002;3.14661
120.45000;71.92667;19.98619;-8.764822e-002;3.14662
120.46500;71.95333;19.98544;-8.687219e-002;3.14663
120.47800;71.98000;19.98559;-8.751736e-002;3.14663
120.49100;72.00667;19.98544;-8.803333e-002;3.14664
120.50600;72.03333;19.98650;-8.854918e-002;3.14665
120.51900;72.06000;19.98831;-8.906514e-002;3.14666
120.53200;72.08667;19.98680;-8.893518e-002;3.14667
120.54700;72.11333;19.98741;-8.867591e-002;3.14668
120.55800;72.14000;19.98619;-8.919200e-002;3.14669
120.57200;72.16667;19.98559;-8.893279e-002;3.14670
120.58300;72.19333;19.98407;-8.931968e-002;3.14670
120.59800;72.22000;19.98559;-8.957715e-002;3.14671
120.61000;72.24667;19.98559;-8.996398e-002;3.14672
120.62400;72.27333;19.98392;-9.060906e-002;3.14673
120.63800;72.30000;19.98498;-9.099576e-002;3.14674
120.65100;72.32667;19.98589;-9.112417e-002;3.14675
120.66200;72.35333;19.98453;-9.215695e-002;3.14675
120.67800;72.38000;19.98392;-9.163927e-002;3.14677
120.69200;72.40667;19.98498;-9.138006e-002;3.14677
120.70500;72.43333;19.98407;-9.280026e-002;3.14678
120.71800;72.46000;19.98392;-9.292865e-002;3.14679
120.73000;72.48667;19.98377;-9.292793e-002;3.14680
120.74300;72.51333;19.98438;-9.344386e-002;3.14681
120.75600;72.54000;19.98453;-9.383061e-002;3.14682
120.76800;72.56667;19.98392;-9.447578e-002;3.14682
120.78200;72.59333;19.98407;-9.499164e-002;3.14683
120.79600;72.62000;19.98498;-9.576586e-002;3.14684
120.80900;72.64667;19.98574;-9.589424e-002;3.14685
120.82200;72.67333;19.98468;-9.628097e-002;3.14686
120.83400;72.70000;19.98589;-9.640942e-002;3.14687
120.84800;72.72667;19.98301;-9.679610e-002;3.14688
120.86100;72.75333;19.98256;-9.679530e-002;3.14688
120.87500;72.78000;19.98498;-9.782785e-002;3.14689
120.88900;72.80667;19.98741;-9.795616e-002;3.14690
120.90200;72.83333;19.98544;-9.847206e-002;3.14691
120.91500;72.86000;19.98453;-9.976301e-002;3.14692
120.93000;72.88667;19.98438;-9.976209e-002;3.14693
120.94300;72.91333;19.98347;      -0.10002;3.14694
120.95700;72.94000;19.98240;      -0.10118;3.14695
120.97100;72.96667;19.98316;      -0.10260;3.14696
120.98500;72.99333;19.98271;      -0.10312;3.14696
120.99900;73.02000;19.98362;      -0.10389;3.14697
121.01300;73.04667;19.98483;      -0.10492;3.14698
121.02800;73.07333;19.98377;      -0.10596;3.14699
121.03900;73.10000;19.98195;      -0.10647;3.14700
121.05400;73.12667;19.98331;      -0.10828;3.14701
121.06800;73.15333;19.98468;      -0.10802;3.14702
121.08000;73.18000;19.98134;      -0.10841;3.14703
121.09300;73.20667;19.98180;      -0.10892;3.14703
121.10700;73.23333;19.98422;      -0.10944;3.14704
121.11900;73.26000;19.98286;      -0.10879;3.14705
121.13200;73.28667;19.98635;      -0.11034;3.14706
121.14600;73.31333;19.98619;      -0.10982;3.14707
121.15700;73.34000;19.98513;      -0.11034;3.14708
121.17100;73.36667;19.98816;      -0.11073;3.14709
121.18400;73.39333;19.98756;      -0.11150;3.14709
121.19700;73.42000;19.98665;      -0.11111;3.14710
121.21000;73.44667;19.98665;      -0.11176;3.14711
121.22500;73.47333;19.98665;      -0.11214;3.14712
121.23700;73.50000;19.98559;      -0.11318;3.14713
121.25200;73.52667;19.98528;      -0.11511;3.14714
121.26500;73.55333;19.98589;      -0.11679;3.14715
121.28000;73.58000;19.98680;      -0.11808;3.14716
121.29300;73.60667;19.98574;      -0.11911;3.14716
121.30700;73.63333;19.98604;      -0.12041;3.14717
121.31900;73.66000;19.98559;      -0.12053;3.14718
121.33200;73.68667;19.98619;      -0.12170;3.14719
121.34300;73.71333;19.98589;      -0.12260;3.14720
121.35600;73.74000;19.98589;      -0.12260;3.14720
121.36900;73.76667;19.98710;      -0.12350;3.14721
121.38300;73.79333;19.98786;      -0.12337;3.14722
121.39700;73.82000;19.98877;      -0.12595;3.14723
121.40900;73.84667;19.98635;      -0.12634;3.14724
121.42300;73.87333;19.98559;      -0.12737;3.14725
121.43700;73.90000;19.98438;      -0.12879;3.14726
121.44900;73.92667;19.98407;      -0.13021;3.14726
121.46400;73.95333;19.98619;      -0.13331;3.14727
121.47900;73.98000;19.98771;      -0.13538;3.14728
121.49200;74.00667;19.98635;      -0.13705;3.14729
121.50600;74.03333;19.98544;      -0.13925;3.14730
121.51900;74.06000;19.98574;      -0.14093;3.14731
121.53100;74.08667;19.98483;      -0.14222;3.14732
121.54500;74.11333;19.98619;      -0.14364;3.14732
121.55900;74.14000;19.98695;      -0.14609;3.14733
121.57000;74.16667;19.98468;      -0.14712;3.14734
121.58300;74.19333;19.98483;      -0.14829;3.14735
121.59800;74.22000;19.98831;      -0.15048;3.14736
121.61000;74.24667;19.98816;      -0.15280;3.14737
121.62300;74.27333;19.98665;      -0.15435;3.14737
121.63500;74.30000;19.98604;      -0.15629;3.14738
121.65000;74.32667;19.98635;      -0.15835;3.14739
121.66200;74.35333;19.98483;      -0.16029;3.14740
121.67700;74.38000;19.98331;      -0.16326;3.14741
121.69000;74.40667;19.98438;      -0.16688;3.14742
121.70300;74.43333;19.98468;      -0.16868;3.14742
121.71600;74.46000;19.98498;      -0.17204;3.14743
121.72900;74.48667;19.98513;      -0.17462;3.14744
121.74200;74.51333;19.98589;      -0.17811;3.14745
121.75400;74.54000;19.98574;      -0.18004;3.14746
121.76800;74.56667;19.98468;      -0.18340;3.14747
121.78100;74.59333;19.98559;      -0.18728;3.14747
121.79200;74.62000;19.98331;      -0.19089;3.14748
121.80500;74.64667;19.98392;      -0.19296;3.14749
121.81900;74.67333;19.98468;      -0.19735;3.14750
121.83300;74.70000;19.98331;      -0.20225;3.14751
121.84600;74.72667;19.98195;      -0.20638;3.14752
121.85900;74.75333;19.98362;      -0.21219;3.14752
121.87400;74.78000;19.98422;      -0.21839;3.14753
121.88800;74.80667;19.98407;      -0.22459;3.14754
121.90100;74.83333;19.98422;      -0.22937;3.14755
121.91500;74.86000;19.98331;      -0.23570;3.14756
121.92900;74.88667;19.98347;      -0.24267;3.14757
121.94100;74.91333;19.98271;      -0.24861;3.14758
121.95400;74.94000;19.98195;      -0.25571;3.14758
121.96900;74.96667;19.98256;      -0.26036;3.14759
121.98200;74.99333;19.98453;      -0.26888;3.14760
121.99600;75.02000;19.98422;      -0.27689;3.14761
122.00900;75.04667;19.98544;      -0.28567;3.14762
122.02100;75.07333;19.98392;      -0.29432;3.14763
122.03500;75.10000;19.98301;      -0.30362;3.14763
122.04800;75.12667;19.98195;      -0.31498;3.14764
122.06100;75.15333;19.98271;      -0.32402;3.14765
122.07600;75.18000;19.98240;      -0.33319;3.14766
122.09000;75.20667;19.98240;      -0.34300;3.14767
122.10300;75.23333;19.98422;      -0.35527;3.14768
122.11500;75.26000;19.98119;      -0.36456;3.14768
122.12900;75.28667;19.98210;      -0.37631;3.14769
122.14300;75.31333;19.98483;      -0.39013;3.14770
122.15500;75.34000;19.98544;      -0.40524;3.14771
122.17000;75.36667;19.98498;      -0.41983;3.14772
122.18300;75.39333;19.98362;      -0.43339;3.14773
122.19600;75.42000;19.98544;      -0.44992;3.14774
122.21000;75.44667;19.98483;      -0.46774;3.14774
122.22300;75.47333;19.98498;      -0.48349;3.14775
122.23500;75.50000;19.98559;      -0.50079;3.14776
122.24900;75.52667;19.98589;      -0.51758;3.14777
122.25900;75.55333;19.98347;      -0.53605;3.14777
122.27500;75.58000;19.98286;      -0.55386;3.14778
122.28800;75.60667;19.98316;      -0.57336;3.14779
122.30100;75.63333;19.98407;      -0.59454;3.14780
122.31300;75.66000;19.98695;      -0.61623;3.14781
122.32600;75.68667;19.98710;      -0.63728;3.14782
122.33900;75.71333;19.98771;      -0.65859;3.14782
122.35300;75.74000;19.98725;      -0.68015;3.14783
122.36600;75.76667;19.98574;      -0.70326;3.14784
122.37700;75.79333;19.98559;      -0.72793;3.14785
122.39200;75.82000;19.98725;      -0.75375;3.14786
122.40600;75.84667;19.98877;      -0.78164;3.14787
122.41900;75.87333;19.98877;      -0.80850;3.14787
122.43300;75.90000;19.98771;      -0.83394;3.14788
122.44500;75.92667;19.98650;      -0.86066;3.14789
122.45800;75.95333;19.98635;      -0.89036;3.14790
122.47000;75.98000;19.98589;      -0.91890;3.14791
122.48500;76.00667;19.98513;      -0.94769;3.14792
122.49900;76.03333;19.98483;      -0.97920;3.14792
122.51200;76.06000;19.98589;      -1.01019;3.14793
122.52600;76.08667;19.98362;      -1.04092;3.14794
122.54000;76.11333;19.98347;      -1.07384;3.14795
122.55400;76.14000;19.98331;      -1.10638;3.14796
122.56700;76.16667;19.98559;      -1.14150;3.14797
122.58100;76.19333;19.98544;      -1.17572;3.14797
122.59300;76.22000;19.98483;      -1.20851;3.14798
122.60500;76.24667;19.98392;      -1.23899;3.14799
122.61900;76.27333;19.98195;      -1.27126;3.14800
122.63200;76.30000;19.98256;      -1.30509;3.14801
122.64500;76.32667;19.98195;      -1.33983;3.14801
122.65900;76.35333;19.98453;      -1.37339;3.14802
122.67400;76.38000;19.98407;      -1.40903;3.14803
122.68900;76.40667;19.98362;      -1.44363;3.14804
122.70100;76.43333;19.98574;      -1.48017;3.14805
122.71500;76.46000;19.98619;      -1.51464;3.14806
122.73000;76.48667;19.98741;      -1.54873;3.14807
122.74400;76.51333;19.98725;      -1.58217;3.14807
122.75500;76.54000;19.98771;      -1.61664;3.14808
122.76900;76.56667;19.98756;      -1.64995;3.14809
122.78200;76.59333;19.98695;      -1.68442;3.14810
122.79500;76.62000;19.98710;      -1.71528;3.14811
122.80800;76.64667;19.98619;      -1.74614;3.14811
122.82200;76.67333;19.98498;      -1.77699;3.14812
122.83400;76.70000;19.98483;      -1.80669;3.14813
122.84700;76.72667;19.98225;      -1.83548;3.14814
122.86200;76.75333;19.98331;      -1.86104;3.14815
122.87600;76.78000;19.98286;      -1.88531;3.14816
122.89000;76.80667;19.98407;      -1.90738;3.14816
122.90400;76.83333;19.98544;      -1.92610;3.14817
122.91700;76.86000;19.98710;      -1.94365;3.14818
122.93000;76.88667;19.98559;      -1.95708;3.14819
122.94300;76.91333;19.98422;      -1.96185;3.14820
122.95600;76.94000;19.98422;      -1.95319;3.14820
122.97100;76.96667;19.98256;      -1.94027;3.14821
122.98300;76.99333;19.98165;      -1.92258;3.14822
122.99500;77.02000;19.97953;      -1.89352;3.14823
123.01000;77.04667;19.98134;      -1.86330;3.14824
123.02300;77.07333;19.98256;      -1.82443;3.14825
123.03600;77.10000;19.98347;      -1.76322;3.14825
123.04900;77.12667;19.98377;      -1.68587;3.14826
123.06300;77.15333;19.98483;      -1.58942;3.14827
123.07600;77.18000;19.98422;      -1.45758;3.14828
123.09100;77.20667;19.98453;      -1.28494;3.14829
123.10300;77.23333;19.98453;      -1.08532;3.14829
123.11800;77.26000;19.98513;      -0.85084;3.14830
123.13000;77.28667;19.98544;      -0.66284;3.14831
123.14400;77.31333;19.98483;      -0.52133;3.14832
123.15800;77.34000;19.98438;      -0.41416;3.14833
123.17100;77.36667;19.98544;      -0.33087;3.14834
123.18500;77.39333;19.98953;      -0.27019;3.14834
123.19800;77.42000;19.98786;      -0.22332;3.14835
123.21100;77.44667;19.98559;      -0.18768;3.14836
123.22500;77.47333;19.98513;      -0.16147;3.14837
123.23700;77.50000;19.98650;      -0.14042;3.14838
123.25100;77.52667;19.98240;      -0.12557;3.14838
123.26300;77.55333;19.98544;      -0.11447;3.14839
123.27800;77.58000;19.98453;      -0.10620;3.14840
123.29200;77.60667;19.98574;-9.974672e-002;3.14841
123.30500;77.63333;19.98589;-9.432315e-002;3.14842
123.31900;77.66000;19.98513;-9.006156e-002;3.14843
123.33100;77.68667;19.98604;-8.760772e-002;3.14843
123.34500;77.71333;19.98725;-8.515376e-002;3.14844
123.35900;77.74000;19.98847;-8.321627e-002;3.14845
123.37100;77.76667;19.98953;-8.269913e-002;3.14846
123.38500;77.79333;19.98801;-8.140721e-002;3.14847
123.39900;77.82000;19.98756;-8.101908e-002;3.14847
123.41400;77.84667;19.98710;-7.998534e-002;3.14848
123.42600;77.87333;19.98665;-8.011377e-002;3.14849
123.44000;77.90000;19.98741;-7.985475e-002;3.14850
123.45300;77.92667;19.98650;-7.856292e-002;3.14851
123.46800;77.95333;19.98816;-7.946584e-002;3.14852
123.48000;77.98000;19.98725;-7.920694e-002;3.14852
123.49300;78.00667;19.98604;-7.868977e-002;3.14853
123.50600;78.03333;19.98483;-7.907636e-002;3.14854
123.52100;78.06000;19.98528;-7.907552e-002;3.14855
123.53300;78.08667;19.98695;-7.881663e-002;3.14855
123.54600;78.11333;19.98574;-7.894500e-002;3.14856
123.55900;78.14000;19.98513;-7.791141e-002;3.14857
123.57100;78.16667;19.98468;-7.791073e-002;3.14858
123.58600;78.19333;19.98468;-7.790990e-002;3.14859
123.59800;78.22000;19.98407;-7.713458e-002;3.14859
123.61100;78.24667;19.98468;-7.752117e-002;3.14860
123.62300;78.27333;19.98362;-7.764960e-002;3.14861
123.63600;78.30000;19.98347;-7.803619e-002;3.14862
123.64900;78.32667;19.98271;-7.816457e-002;3.14862
123.66200;78.35333;19.98165;-7.777652e-002;3.14863
123.67500;78.38000;19.98165;-7.764669e-002;3.14864
123.69000;78.40667;19.98165;-7.816227e-002;3.14865
123.70200;78.43333;19.98316;-7.841980e-002;3.14866
123.71400;78.46000;19.98301;-7.790271e-002;3.14866
123.72700;78.48667;19.98438;-7.790198e-002;3.14867
123.74000;78.51333;19.98362;-7.777215e-002;3.14868
123.75200;78.54000;19.98438;-7.764237e-002;3.14869
123.76500;78.56667;19.98453;-7.802895e-002;3.14869
123.78000;78.59333;19.98377;-7.789901e-002;3.14870
123.79300;78.62000;19.98483;-7.712367e-002;3.14871
123.80800;78.64667;19.98665;-7.828474e-002;3.14872
123.82200;78.67333;19.98589;-7.828395e-002;3.14873
123.83500;78.70000;19.98574;-7.828323e-002;3.14874
123.84900;78.72667;19.98635;-7.776604e-002;3.14874
123.86200;78.75333;19.98665;-7.866902e-002;3.14875
123.87600;78.78000;19.98831;-7.892643e-002;3.14876
123.89000;78.80667;19.98650;-7.892564e-002;3.14877
123.90300;78.83333;19.98786;-7.827941e-002;3.14878
123.91600;78.86000;19.98771;-7.918237e-002;3.14878
123.93000;78.88667;19.98619;-7.866519e-002;3.14879
123.94300;78.91333;19.98847;-7.840627e-002;3.14880
123.95500;78.94000;19.98680;-7.763101e-002;3.14881
123.96800;78.96667;19.98801;-7.827577e-002;3.14881
123.98100;78.99333;19.98619;-7.788775e-002;3.14882
123.99400;79.02000;19.98589;-7.788702e-002;3.14883
124.00800;79.04667;19.98574;-7.762804e-002;3.14884
124.02100;79.07333;19.98695;-7.878918e-002;3.14885
124.03300;79.10000;19.98498;-7.801393e-002;3.14885
124.04700;79.12667;19.98559;-7.775496e-002;3.14886
124.05900;79.15333;19.98468;-7.762520e-002;3.14887
124.07400;79.18000;19.98544;-7.839893e-002;3.14888
124.08800;79.20667;19.98544;-7.917271e-002;3.14889
124.10000;79.23333;19.98544;-7.930113e-002;3.14889
124.11200;79.26000;19.98271;-7.852589e-002;3.14890
124.12600;79.28667;19.98528;-7.968695e-002;3.14891
124.13800;79.31333;19.98362;-7.904081e-002;3.14891
124.15200;79.34000;19.98256;-7.891093e-002;3.14892
124.16400;79.36667;19.98316;-7.878116e-002;3.14893
124.17900;79.39333;19.98483;-7.878033e-002;3.14894
124.19300;79.42000;19.98392;-7.877954e-002;3.14895
124.20400;79.44667;19.98210;-7.813346e-002;3.14895
124.21800;79.47333;19.98392;-7.851995e-002;3.14896
124.23100;79.50000;19.98438;-7.942287e-002;3.14897
124.24600;79.52667;19.98407;-7.929294e-002;3.14898
124.25900;79.55333;19.98483;-7.942130e-002;3.14899
124.27200;79.58000;19.98665;-7.942057e-002;3.14899
124.28500;79.60667;19.98756;-7.929075e-002;3.14900
124.29900;79.63333;19.98862;-7.903178e-002;3.14901
124.31100;79.66000;19.98801;-7.903111e-002;3.14902
124.32400;79.68667;19.98741;-7.941765e-002;3.14902
124.33700;79.71333;19.98862;-7.980419e-002;3.14903
124.35100;79.74000;19.98816;-7.967431e-002;3.14904
124.36500;79.76667;19.98953;-7.967352e-002;3.14905
124.37900;79.79333;19.98877;-7.889822e-002;3.14906
124.39200;79.82000;19.98831;-7.876840e-002;3.14906
124.40400;79.84667;19.98831;-7.915499e-002;3.14907
124.41800;79.87333;19.98862;-7.915421e-002;3.14908
124.43100;79.90000;19.98983;-7.966982e-002;3.14909
124.44400;79.92667;19.99059;-8.044361e-002;3.14909
124.45600;79.95333;19.98892;-7.953934e-002;3.14910
124.46900;79.98000;19.98816;-7.928044e-002;3.14911
124.48300;80.00667;19.98725;-7.927965e-002;3.14912
124.49500;80.03333;19.98847;-7.966623e-002;3.14912
124.50900;80.06000;19.99225;-8.031088e-002;3.14913
124.52200;80.08667;19.98710;-7.901930e-002;3.14914
124.53600;80.11333;19.98847;-7.940577e-002;3.14915
124.54900;80.14000;19.99074;-7.979229e-002;3.14916
124.56100;80.16667;19.98953;-7.992070e-002;3.14916
124.57500;80.19333;19.98801;-7.979083e-002;3.14917
124.59000;80.22000;19.98877;-8.017724e-002;3.14918
124.60200;80.24667;19.98695;-8.043474e-002;3.14919
124.61500;80.27333;19.98756;-8.043400e-002;3.14919
124.62800;80.30000;19.98619;-7.978787e-002;3.14920
124.64100;80.32667;19.98574;-8.043254e-002;3.14921
124.65400;80.35333;19.98559;-8.056090e-002;3.14922
124.66800;80.38000;19.98604;-8.030194e-002;3.14922
124.68100;80.40667;19.98604;-8.030122e-002;3.14923
124.69400;80.43333;19.98528;-8.042957e-002;3.14924
124.70700;80.46000;19.98422;-8.055792e-002;3.14925
124.72000;80.48667;19.98331;-7.965363e-002;3.14925
124.73300;80.51333;19.98301;-7.991107e-002;3.14926
124.74600;80.54000;19.98392;-8.029757e-002;3.14927
124.75900;80.56667;19.98240;-7.990960e-002;3.14928
124.77300;80.59333;19.98407;-8.055422e-002;3.14929
124.78700;80.62000;19.98498;-8.081159e-002;3.14929
124.80000;80.64667;19.98498;-8.093994e-002;3.14930
124.81300;80.67333;19.98559;-8.068106e-002;3.14931
124.82600;80.70000;19.98544;-8.055124e-002;3.14932
124.83900;80.72667;19.98619;-8.080867e-002;3.14932
124.85100;80.75333;19.98422;-8.016261e-002;3.14933
124.86600;80.78000;19.98271;-8.016177e-002;3.14934
124.87700;80.80667;19.98059;-8.054839e-002;3.14935
124.89200;80.83333;19.98468;-8.183831e-002;3.14935
124.90600;80.86000;19.98407;-8.119214e-002;3.14936
124.91800;80.88667;19.98240;-8.093331e-002;3.14937
124.93200;80.91333;19.98468;-8.106160e-002;3.14938
124.94400;80.94000;19.98362;-8.157723e-002;3.14938
124.95800;80.96667;19.98589;-8.106014e-002;3.14939
124.97000;80.99333;19.98347;-8.131761e-002;3.14940
124.98600;81.02000;19.98438;-8.118764e-002;3.14941
125.00000;81.04667;19.98498;-8.144500e-002;3.14942
125.01300;81.07333;19.98544;-8.208964e-002;3.14942
125.02600;81.10000;19.98635;-8.183076e-002;3.14943
125.03900;81.12667;19.98725;-8.221725e-002;3.14944
125.05200;81.15333;19.98650;-8.144208e-002;3.14945
125.06600;81.18000;19.98786;-8.182852e-002;3.14945
125.07800;81.20667;19.98650;-8.156970e-002;3.14946
125.09300;81.23333;19.98756;-8.105258e-002;3.14947
125.10500;81.26000;19.98650;-8.092283e-002;3.14948
125.11900;81.28667;19.98635;-8.156739e-002;3.14948
125.13200;81.31333;19.98619;-8.169573e-002;3.14949
125.14400;81.34000;19.98619;-8.104972e-002;3.14950
125.16000;81.36667;19.98665;-8.143603e-002;3.14951
125.17400;81.39333;19.98741;-8.182246e-002;3.14952
125.18800;81.42000;19.98695;-8.233794e-002;3.14952
125.20100;81.44667;19.98877;-8.195000e-002;3.14953
125.21500;81.47333;19.98907;-8.220736e-002;3.14954
125.22700;81.50000;19.98816;-8.194855e-002;3.14955
125.24200;81.52667;19.98771;-8.181864e-002;3.14955
125.25400;81.55333;19.98756;-8.272143e-002;3.14956
125.26700;81.58000;19.98771;-8.272070e-002;3.14957
125.28000;81.60667;19.98862;-8.297811e-002;3.14958
125.29300;81.63333;19.98862;-8.233204e-002;3.14958
125.30600;81.66000;19.98907;-8.194411e-002;3.14959
125.32000;81.68667;19.99059;-8.284679e-002;3.14960
125.33200;81.71333;19.99013;-8.181360e-002;3.14961
125.34600;81.74000;19.98771;-8.129655e-002;3.14961
125.35800;81.76667;19.98816;-8.090869e-002;3.14962
125.37200;81.79333;19.98816;-8.129509e-002;3.14963
125.38700;81.82000;19.98695;-8.155239e-002;3.14964
125.40000;81.84667;19.98695;-8.245510e-002;3.14964
125.41400;81.87333;19.98635;-8.258338e-002;3.14965
125.42600;81.90000;19.98680;-8.284083e-002;3.14966
125.44000;81.92667;19.98650;-8.232379e-002;3.14967
125.45400;81.95333;19.98589;-8.271020e-002;3.14967
125.46900;81.98000;19.98559;-8.232217e-002;3.14968
125.48000;82.00667;19.98528;-8.141812e-002;3.14969
125.49300;82.03333;19.98468;-8.244988e-002;3.14970
125.50700;82.06000;19.98438;-8.180379e-002;3.14970
125.52100;82.08667;19.98377;-8.206114e-002;3.14971
125.53300;82.11333;19.98377;-8.244764e-002;3.14972
125.54700;82.14000;19.98377;-8.205967e-002;3.14973
125.56000;82.16667;19.98453;-8.205895e-002;3.14973
125.57400;82.19333;19.98347;-8.257440e-002;3.14974
125.58900;82.22000;19.98438;-8.218638e-002;3.14975
125.60100;82.24667;19.98438;-8.283101e-002;3.14976
125.61500;82.27333;19.98544;-8.257211e-002;3.14977
125.62800;82.30000;19.98392;-8.244232e-002;3.14977
125.64100;82.32667;19.98438;-8.218347e-002;3.14978
125.65400;82.35333;19.98589;-8.166651e-002;3.14979
125.66800;82.38000;19.98422;-8.244008e-002;3.14979
125.68100;82.40667;19.98574;-8.218123e-002;3.14980
125.69400;82.43333;19.98619;-8.218051e-002;3.14981
125.70700;82.46000;19.98528;-8.179261e-002;3.14982
125.72200;82.48667;19.98786;-8.321138e-002;3.14983
125.73400;82.51333;19.98483;-8.217828e-002;3.14983
125.74900;82.54000;19.98513;-8.282271e-002;3.14984
125.76100;82.56667;19.98559;-8.243486e-002;3.14985
125.76800;82.58000;19.98528;-8.243448e-002;3.14985